[2023-03-22 07:53:06,519] {taskinstance.py:1035} INFO - Dependencies all met for <TaskInstance: load_to_datamart.load_to_datamart manual__2023-03-22T07:53:02.464565+00:00 [queued]>
[2023-03-22 07:53:06,571] {taskinstance.py:1035} INFO - Dependencies all met for <TaskInstance: load_to_datamart.load_to_datamart manual__2023-03-22T07:53:02.464565+00:00 [queued]>
[2023-03-22 07:53:06,571] {taskinstance.py:1241} INFO - 
--------------------------------------------------------------------------------
[2023-03-22 07:53:06,572] {taskinstance.py:1242} INFO - Starting attempt 1 of 1
[2023-03-22 07:53:06,573] {taskinstance.py:1243} INFO - 
--------------------------------------------------------------------------------
[2023-03-22 07:53:06,593] {taskinstance.py:1262} INFO - Executing <Task(PythonOperator): load_to_datamart> on 2023-03-22 07:53:02.464565+00:00
[2023-03-22 07:53:06,599] {standard_task_runner.py:52} INFO - Started process 270 to run task
[2023-03-22 07:53:06,604] {standard_task_runner.py:76} INFO - Running: ['***', 'tasks', 'run', 'load_to_datamart', 'load_to_datamart', 'manual__2023-03-22T07:53:02.464565+00:00', '--job-id', '8', '--raw', '--subdir', 'DAGS_FOLDER/mart_layer.py', '--cfg-path', '/tmp/tmpdr46muoc', '--error-file', '/tmp/tmp34w6dqz5']
[2023-03-22 07:53:06,605] {standard_task_runner.py:77} INFO - Job 8: Subtask load_to_datamart
[2023-03-22 07:53:06,685] {logging_mixin.py:109} INFO - Running <TaskInstance: load_to_datamart.load_to_datamart manual__2023-03-22T07:53:02.464565+00:00 [running]> on host c456fd334a3e
[2023-03-22 07:53:06,781] {taskinstance.py:1414} INFO - Exporting the following env vars:
AIRFLOW_CTX_DAG_OWNER=***
AIRFLOW_CTX_DAG_ID=load_to_datamart
AIRFLOW_CTX_TASK_ID=load_to_datamart
AIRFLOW_CTX_EXECUTION_DATE=2023-03-22T07:53:02.464565+00:00
AIRFLOW_CTX_DAG_RUN_ID=manual__2023-03-22T07:53:02.464565+00:00
[2023-03-22 07:53:07,362] {taskinstance.py:1686} ERROR - Task failed with exception
Traceback (most recent call last):
  File "/home/airflow/.local/lib/python3.6/site-packages/sqlalchemy/engine/base.py", line 1277, in _execute_context
    cursor, statement, parameters, context
  File "/home/airflow/.local/lib/python3.6/site-packages/sqlalchemy/engine/default.py", line 608, in do_execute
    cursor.execute(statement, parameters)
psycopg2.errors.InvalidSchemaName: no schema has been selected to create in
LINE 2: CREATE TABLE fact_store (
                     ^


The above exception was the direct cause of the following exception:

Traceback (most recent call last):
  File "/home/airflow/.local/lib/python3.6/site-packages/airflow/models/taskinstance.py", line 1324, in _run_raw_task
    self._execute_task_with_callbacks(context)
  File "/home/airflow/.local/lib/python3.6/site-packages/airflow/models/taskinstance.py", line 1443, in _execute_task_with_callbacks
    result = self._execute_task(context, self.task)
  File "/home/airflow/.local/lib/python3.6/site-packages/airflow/models/taskinstance.py", line 1499, in _execute_task
    result = execute_callable(context=context)
  File "/home/airflow/.local/lib/python3.6/site-packages/airflow/operators/python.py", line 151, in execute
    return_value = self.execute_callable()
  File "/home/airflow/.local/lib/python3.6/site-packages/airflow/operators/python.py", line 162, in execute_callable
    return self.python_callable(*self.op_args, **self.op_kwargs)
  File "/opt/airflow/dags/script/main_datamart.py", line 12, in load_datamart
    df_store.to_sql("fact_store",engine_1)
  File "/home/airflow/.local/lib/python3.6/site-packages/pandas/core/generic.py", line 2615, in to_sql
    method=method,
  File "/home/airflow/.local/lib/python3.6/site-packages/pandas/io/sql.py", line 598, in to_sql
    method=method,
  File "/home/airflow/.local/lib/python3.6/site-packages/pandas/io/sql.py", line 1393, in to_sql
    table.create()
  File "/home/airflow/.local/lib/python3.6/site-packages/pandas/io/sql.py", line 732, in create
    self._execute_create()
  File "/home/airflow/.local/lib/python3.6/site-packages/pandas/io/sql.py", line 718, in _execute_create
    self.table.create()
  File "/home/airflow/.local/lib/python3.6/site-packages/sqlalchemy/sql/schema.py", line 928, in create
    bind._run_visitor(ddl.SchemaGenerator, self, checkfirst=checkfirst)
  File "/home/airflow/.local/lib/python3.6/site-packages/sqlalchemy/engine/base.py", line 2095, in _run_visitor
    conn._run_visitor(visitorcallable, element, **kwargs)
  File "/home/airflow/.local/lib/python3.6/site-packages/sqlalchemy/engine/base.py", line 1656, in _run_visitor
    visitorcallable(self.dialect, self, **kwargs).traverse_single(element)
  File "/home/airflow/.local/lib/python3.6/site-packages/sqlalchemy/sql/visitors.py", line 145, in traverse_single
    return meth(obj, **kw)
  File "/home/airflow/.local/lib/python3.6/site-packages/sqlalchemy/sql/ddl.py", line 832, in visit_table
    include_foreign_key_constraints,  # noqa
  File "/home/airflow/.local/lib/python3.6/site-packages/sqlalchemy/engine/base.py", line 1011, in execute
    return meth(self, multiparams, params)
  File "/home/airflow/.local/lib/python3.6/site-packages/sqlalchemy/sql/ddl.py", line 72, in _execute_on_connection
    return connection._execute_ddl(self, multiparams, params)
  File "/home/airflow/.local/lib/python3.6/site-packages/sqlalchemy/engine/base.py", line 1073, in _execute_ddl
    compiled,
  File "/home/airflow/.local/lib/python3.6/site-packages/sqlalchemy/engine/base.py", line 1317, in _execute_context
    e, statement, parameters, cursor, context
  File "/home/airflow/.local/lib/python3.6/site-packages/sqlalchemy/engine/base.py", line 1511, in _handle_dbapi_exception
    sqlalchemy_exception, with_traceback=exc_info[2], from_=e
  File "/home/airflow/.local/lib/python3.6/site-packages/sqlalchemy/util/compat.py", line 182, in raise_
    raise exception
  File "/home/airflow/.local/lib/python3.6/site-packages/sqlalchemy/engine/base.py", line 1277, in _execute_context
    cursor, statement, parameters, context
  File "/home/airflow/.local/lib/python3.6/site-packages/sqlalchemy/engine/default.py", line 608, in do_execute
    cursor.execute(statement, parameters)
sqlalchemy.exc.ProgrammingError: (psycopg2.errors.InvalidSchemaName) no schema has been selected to create in
LINE 2: CREATE TABLE fact_store (
                     ^

[SQL: 
CREATE TABLE fact_store (
	index BIGINT, 
	business_id TEXT, 
	store TEXT, 
	feature_restaurant TEXT, 
	tema_business TEXT, 
	address TEXT, 
	city TEXT, 
	postal_code TEXT, 
	state TEXT, 
	day_hours TEXT, 
	date TEXT, 
	stars FLOAT(53), 
	review_count BIGINT
)

]
(Background on this error at: http://sqlalche.me/e/13/f405)
[2023-03-22 07:53:07,418] {taskinstance.py:1280} INFO - Marking task as FAILED. dag_id=load_to_datamart, task_id=load_to_datamart, execution_date=20230322T075302, start_date=20230322T075306, end_date=20230322T075307
[2023-03-22 07:53:07,464] {standard_task_runner.py:91} ERROR - Failed to execute job 8 for task load_to_datamart
Traceback (most recent call last):
  File "/home/airflow/.local/lib/python3.6/site-packages/sqlalchemy/engine/base.py", line 1277, in _execute_context
    cursor, statement, parameters, context
  File "/home/airflow/.local/lib/python3.6/site-packages/sqlalchemy/engine/default.py", line 608, in do_execute
    cursor.execute(statement, parameters)
psycopg2.errors.InvalidSchemaName: no schema has been selected to create in
LINE 2: CREATE TABLE fact_store (
                     ^


The above exception was the direct cause of the following exception:

Traceback (most recent call last):
  File "/home/airflow/.local/lib/python3.6/site-packages/airflow/task/task_runner/standard_task_runner.py", line 85, in _start_by_fork
    args.func(args, dag=self.dag)
  File "/home/airflow/.local/lib/python3.6/site-packages/airflow/cli/cli_parser.py", line 48, in command
    return func(*args, **kwargs)
  File "/home/airflow/.local/lib/python3.6/site-packages/airflow/utils/cli.py", line 92, in wrapper
    return f(*args, **kwargs)
  File "/home/airflow/.local/lib/python3.6/site-packages/airflow/cli/commands/task_command.py", line 292, in task_run
    _run_task_by_selected_method(args, dag, ti)
  File "/home/airflow/.local/lib/python3.6/site-packages/airflow/cli/commands/task_command.py", line 107, in _run_task_by_selected_method
    _run_raw_task(args, ti)
  File "/home/airflow/.local/lib/python3.6/site-packages/airflow/cli/commands/task_command.py", line 184, in _run_raw_task
    error_file=args.error_file,
  File "/home/airflow/.local/lib/python3.6/site-packages/airflow/utils/session.py", line 70, in wrapper
    return func(*args, session=session, **kwargs)
  File "/home/airflow/.local/lib/python3.6/site-packages/airflow/models/taskinstance.py", line 1324, in _run_raw_task
    self._execute_task_with_callbacks(context)
  File "/home/airflow/.local/lib/python3.6/site-packages/airflow/models/taskinstance.py", line 1443, in _execute_task_with_callbacks
    result = self._execute_task(context, self.task)
  File "/home/airflow/.local/lib/python3.6/site-packages/airflow/models/taskinstance.py", line 1499, in _execute_task
    result = execute_callable(context=context)
  File "/home/airflow/.local/lib/python3.6/site-packages/airflow/operators/python.py", line 151, in execute
    return_value = self.execute_callable()
  File "/home/airflow/.local/lib/python3.6/site-packages/airflow/operators/python.py", line 162, in execute_callable
    return self.python_callable(*self.op_args, **self.op_kwargs)
  File "/opt/airflow/dags/script/main_datamart.py", line 12, in load_datamart
    df_store.to_sql("fact_store",engine_1)
  File "/home/airflow/.local/lib/python3.6/site-packages/pandas/core/generic.py", line 2615, in to_sql
    method=method,
  File "/home/airflow/.local/lib/python3.6/site-packages/pandas/io/sql.py", line 598, in to_sql
    method=method,
  File "/home/airflow/.local/lib/python3.6/site-packages/pandas/io/sql.py", line 1393, in to_sql
    table.create()
  File "/home/airflow/.local/lib/python3.6/site-packages/pandas/io/sql.py", line 732, in create
    self._execute_create()
  File "/home/airflow/.local/lib/python3.6/site-packages/pandas/io/sql.py", line 718, in _execute_create
    self.table.create()
  File "/home/airflow/.local/lib/python3.6/site-packages/sqlalchemy/sql/schema.py", line 928, in create
    bind._run_visitor(ddl.SchemaGenerator, self, checkfirst=checkfirst)
  File "/home/airflow/.local/lib/python3.6/site-packages/sqlalchemy/engine/base.py", line 2095, in _run_visitor
    conn._run_visitor(visitorcallable, element, **kwargs)
  File "/home/airflow/.local/lib/python3.6/site-packages/sqlalchemy/engine/base.py", line 1656, in _run_visitor
    visitorcallable(self.dialect, self, **kwargs).traverse_single(element)
  File "/home/airflow/.local/lib/python3.6/site-packages/sqlalchemy/sql/visitors.py", line 145, in traverse_single
    return meth(obj, **kw)
  File "/home/airflow/.local/lib/python3.6/site-packages/sqlalchemy/sql/ddl.py", line 832, in visit_table
    include_foreign_key_constraints,  # noqa
  File "/home/airflow/.local/lib/python3.6/site-packages/sqlalchemy/engine/base.py", line 1011, in execute
    return meth(self, multiparams, params)
  File "/home/airflow/.local/lib/python3.6/site-packages/sqlalchemy/sql/ddl.py", line 72, in _execute_on_connection
    return connection._execute_ddl(self, multiparams, params)
  File "/home/airflow/.local/lib/python3.6/site-packages/sqlalchemy/engine/base.py", line 1073, in _execute_ddl
    compiled,
  File "/home/airflow/.local/lib/python3.6/site-packages/sqlalchemy/engine/base.py", line 1317, in _execute_context
    e, statement, parameters, cursor, context
  File "/home/airflow/.local/lib/python3.6/site-packages/sqlalchemy/engine/base.py", line 1511, in _handle_dbapi_exception
    sqlalchemy_exception, with_traceback=exc_info[2], from_=e
  File "/home/airflow/.local/lib/python3.6/site-packages/sqlalchemy/util/compat.py", line 182, in raise_
    raise exception
  File "/home/airflow/.local/lib/python3.6/site-packages/sqlalchemy/engine/base.py", line 1277, in _execute_context
    cursor, statement, parameters, context
  File "/home/airflow/.local/lib/python3.6/site-packages/sqlalchemy/engine/default.py", line 608, in do_execute
    cursor.execute(statement, parameters)
sqlalchemy.exc.ProgrammingError: (psycopg2.errors.InvalidSchemaName) no schema has been selected to create in
LINE 2: CREATE TABLE fact_store (
                     ^

[SQL: 
CREATE TABLE fact_store (
	index BIGINT, 
	business_id TEXT, 
	store TEXT, 
	feature_restaurant TEXT, 
	tema_business TEXT, 
	address TEXT, 
	city TEXT, 
	postal_code TEXT, 
	state TEXT, 
	day_hours TEXT, 
	date TEXT, 
	stars FLOAT(53), 
	review_count BIGINT
)

]
(Background on this error at: http://sqlalche.me/e/13/f405)
[2023-03-22 07:53:07,498] {local_task_job.py:154} INFO - Task exited with return code 1
[2023-03-22 07:53:07,564] {local_task_job.py:264} INFO - 0 downstream tasks scheduled from follow-on schedule check
