[2023-03-22 03:10:56,638] {taskinstance.py:1035} INFO - Dependencies all met for <TaskInstance: etl_to_staging.trans_csv manual__2023-03-22T03:10:52.655590+00:00 [queued]>
[2023-03-22 03:10:56,659] {taskinstance.py:1035} INFO - Dependencies all met for <TaskInstance: etl_to_staging.trans_csv manual__2023-03-22T03:10:52.655590+00:00 [queued]>
[2023-03-22 03:10:56,659] {taskinstance.py:1241} INFO - 
--------------------------------------------------------------------------------
[2023-03-22 03:10:56,660] {taskinstance.py:1242} INFO - Starting attempt 1 of 1
[2023-03-22 03:10:56,660] {taskinstance.py:1243} INFO - 
--------------------------------------------------------------------------------
[2023-03-22 03:10:56,694] {taskinstance.py:1262} INFO - Executing <Task(PythonOperator): trans_csv> on 2023-03-22 03:10:52.655590+00:00
[2023-03-22 03:10:56,703] {standard_task_runner.py:52} INFO - Started process 325 to run task
[2023-03-22 03:10:56,705] {standard_task_runner.py:76} INFO - Running: ['***', 'tasks', 'run', 'etl_to_staging', 'trans_csv', 'manual__2023-03-22T03:10:52.655590+00:00', '--job-id', '4', '--raw', '--subdir', 'DAGS_FOLDER/etl_staging.py', '--cfg-path', '/tmp/tmpln28tc2_', '--error-file', '/tmp/tmp250lf1vj']
[2023-03-22 03:10:56,706] {standard_task_runner.py:77} INFO - Job 4: Subtask trans_csv
[2023-03-22 03:10:56,748] {logging_mixin.py:109} INFO - Running <TaskInstance: etl_to_staging.trans_csv manual__2023-03-22T03:10:52.655590+00:00 [running]> on host c86027d4d7ad
[2023-03-22 03:10:56,794] {taskinstance.py:1414} INFO - Exporting the following env vars:
AIRFLOW_CTX_DAG_OWNER=***
AIRFLOW_CTX_DAG_ID=etl_to_staging
AIRFLOW_CTX_TASK_ID=trans_csv
AIRFLOW_CTX_EXECUTION_DATE=2023-03-22T03:10:52.655590+00:00
AIRFLOW_CTX_DAG_RUN_ID=manual__2023-03-22T03:10:52.655590+00:00
[2023-03-22 03:10:56,978] {taskinstance.py:1686} ERROR - Task failed with exception
Traceback (most recent call last):
  File "/home/airflow/.local/lib/python3.6/site-packages/pandas/core/indexes/base.py", line 2898, in get_loc
    return self._engine.get_loc(casted_key)
  File "pandas/_libs/index.pyx", line 70, in pandas._libs.index.IndexEngine.get_loc
  File "pandas/_libs/index.pyx", line 101, in pandas._libs.index.IndexEngine.get_loc
  File "pandas/_libs/hashtable_class_helper.pxi", line 1675, in pandas._libs.hashtable.PyObjectHashTable.get_item
  File "pandas/_libs/hashtable_class_helper.pxi", line 1683, in pandas._libs.hashtable.PyObjectHashTable.get_item
KeyError: 'Unnamed: 0'

The above exception was the direct cause of the following exception:

Traceback (most recent call last):
  File "/home/airflow/.local/lib/python3.6/site-packages/airflow/models/taskinstance.py", line 1324, in _run_raw_task
    self._execute_task_with_callbacks(context)
  File "/home/airflow/.local/lib/python3.6/site-packages/airflow/models/taskinstance.py", line 1443, in _execute_task_with_callbacks
    result = self._execute_task(context, self.task)
  File "/home/airflow/.local/lib/python3.6/site-packages/airflow/models/taskinstance.py", line 1499, in _execute_task
    result = execute_callable(context=context)
  File "/home/airflow/.local/lib/python3.6/site-packages/airflow/operators/python.py", line 151, in execute
    return_value = self.execute_callable()
  File "/home/airflow/.local/lib/python3.6/site-packages/airflow/operators/python.py", line 162, in execute_callable
    return self.python_callable(*self.op_args, **self.op_kwargs)
  File "/opt/airflow/dags/script/main.py", line 19, in transform_csv
    data_las_vegas[col] = data_las_vegas[col].astype(str)
  File "/home/airflow/.local/lib/python3.6/site-packages/pandas/core/frame.py", line 2906, in __getitem__
    indexer = self.columns.get_loc(key)
  File "/home/airflow/.local/lib/python3.6/site-packages/pandas/core/indexes/base.py", line 2900, in get_loc
    raise KeyError(key) from err
KeyError: 'Unnamed: 0'
[2023-03-22 03:10:57,004] {taskinstance.py:1280} INFO - Marking task as FAILED. dag_id=etl_to_staging, task_id=trans_csv, execution_date=20230322T031052, start_date=20230322T031056, end_date=20230322T031057
[2023-03-22 03:10:57,019] {standard_task_runner.py:91} ERROR - Failed to execute job 4 for task trans_csv
Traceback (most recent call last):
  File "/home/airflow/.local/lib/python3.6/site-packages/pandas/core/indexes/base.py", line 2898, in get_loc
    return self._engine.get_loc(casted_key)
  File "pandas/_libs/index.pyx", line 70, in pandas._libs.index.IndexEngine.get_loc
  File "pandas/_libs/index.pyx", line 101, in pandas._libs.index.IndexEngine.get_loc
  File "pandas/_libs/hashtable_class_helper.pxi", line 1675, in pandas._libs.hashtable.PyObjectHashTable.get_item
  File "pandas/_libs/hashtable_class_helper.pxi", line 1683, in pandas._libs.hashtable.PyObjectHashTable.get_item
KeyError: 'Unnamed: 0'

The above exception was the direct cause of the following exception:

Traceback (most recent call last):
  File "/home/airflow/.local/lib/python3.6/site-packages/airflow/task/task_runner/standard_task_runner.py", line 85, in _start_by_fork
    args.func(args, dag=self.dag)
  File "/home/airflow/.local/lib/python3.6/site-packages/airflow/cli/cli_parser.py", line 48, in command
    return func(*args, **kwargs)
  File "/home/airflow/.local/lib/python3.6/site-packages/airflow/utils/cli.py", line 92, in wrapper
    return f(*args, **kwargs)
  File "/home/airflow/.local/lib/python3.6/site-packages/airflow/cli/commands/task_command.py", line 292, in task_run
    _run_task_by_selected_method(args, dag, ti)
  File "/home/airflow/.local/lib/python3.6/site-packages/airflow/cli/commands/task_command.py", line 107, in _run_task_by_selected_method
    _run_raw_task(args, ti)
  File "/home/airflow/.local/lib/python3.6/site-packages/airflow/cli/commands/task_command.py", line 184, in _run_raw_task
    error_file=args.error_file,
  File "/home/airflow/.local/lib/python3.6/site-packages/airflow/utils/session.py", line 70, in wrapper
    return func(*args, session=session, **kwargs)
  File "/home/airflow/.local/lib/python3.6/site-packages/airflow/models/taskinstance.py", line 1324, in _run_raw_task
    self._execute_task_with_callbacks(context)
  File "/home/airflow/.local/lib/python3.6/site-packages/airflow/models/taskinstance.py", line 1443, in _execute_task_with_callbacks
    result = self._execute_task(context, self.task)
  File "/home/airflow/.local/lib/python3.6/site-packages/airflow/models/taskinstance.py", line 1499, in _execute_task
    result = execute_callable(context=context)
  File "/home/airflow/.local/lib/python3.6/site-packages/airflow/operators/python.py", line 151, in execute
    return_value = self.execute_callable()
  File "/home/airflow/.local/lib/python3.6/site-packages/airflow/operators/python.py", line 162, in execute_callable
    return self.python_callable(*self.op_args, **self.op_kwargs)
  File "/opt/airflow/dags/script/main.py", line 19, in transform_csv
    data_las_vegas[col] = data_las_vegas[col].astype(str)
  File "/home/airflow/.local/lib/python3.6/site-packages/pandas/core/frame.py", line 2906, in __getitem__
    indexer = self.columns.get_loc(key)
  File "/home/airflow/.local/lib/python3.6/site-packages/pandas/core/indexes/base.py", line 2900, in get_loc
    raise KeyError(key) from err
KeyError: 'Unnamed: 0'
[2023-03-22 03:10:57,039] {local_task_job.py:154} INFO - Task exited with return code 1
[2023-03-22 03:10:57,085] {local_task_job.py:264} INFO - 0 downstream tasks scheduled from follow-on schedule check
