[2023-03-22 07:49:09,257] {taskinstance.py:1035} INFO - Dependencies all met for <TaskInstance: load_to_datamart.load_to_datamart manual__2023-03-22T07:49:03.341650+00:00 [queued]>
[2023-03-22 07:49:09,298] {taskinstance.py:1035} INFO - Dependencies all met for <TaskInstance: load_to_datamart.load_to_datamart manual__2023-03-22T07:49:03.341650+00:00 [queued]>
[2023-03-22 07:49:09,299] {taskinstance.py:1241} INFO - 
--------------------------------------------------------------------------------
[2023-03-22 07:49:09,300] {taskinstance.py:1242} INFO - Starting attempt 1 of 1
[2023-03-22 07:49:09,300] {taskinstance.py:1243} INFO - 
--------------------------------------------------------------------------------
[2023-03-22 07:49:09,328] {taskinstance.py:1262} INFO - Executing <Task(PythonOperator): load_to_datamart> on 2023-03-22 07:49:03.341650+00:00
[2023-03-22 07:49:09,335] {standard_task_runner.py:52} INFO - Started process 142 to run task
[2023-03-22 07:49:09,340] {standard_task_runner.py:76} INFO - Running: ['***', 'tasks', 'run', 'load_to_datamart', 'load_to_datamart', 'manual__2023-03-22T07:49:03.341650+00:00', '--job-id', '4', '--raw', '--subdir', 'DAGS_FOLDER/mart_layer.py', '--cfg-path', '/tmp/tmpl5g58j8p', '--error-file', '/tmp/tmpdet945to']
[2023-03-22 07:49:09,341] {standard_task_runner.py:77} INFO - Job 4: Subtask load_to_datamart
[2023-03-22 07:49:09,412] {logging_mixin.py:109} INFO - Running <TaskInstance: load_to_datamart.load_to_datamart manual__2023-03-22T07:49:03.341650+00:00 [running]> on host c456fd334a3e
[2023-03-22 07:49:09,493] {taskinstance.py:1414} INFO - Exporting the following env vars:
AIRFLOW_CTX_DAG_OWNER=***
AIRFLOW_CTX_DAG_ID=load_to_datamart
AIRFLOW_CTX_TASK_ID=load_to_datamart
AIRFLOW_CTX_EXECUTION_DATE=2023-03-22T07:49:03.341650+00:00
AIRFLOW_CTX_DAG_RUN_ID=manual__2023-03-22T07:49:03.341650+00:00
[2023-03-22 07:49:09,501] {taskinstance.py:1686} ERROR - Task failed with exception
Traceback (most recent call last):
  File "/home/airflow/.local/lib/python3.6/site-packages/airflow/models/taskinstance.py", line 1324, in _run_raw_task
    self._execute_task_with_callbacks(context)
  File "/home/airflow/.local/lib/python3.6/site-packages/airflow/models/taskinstance.py", line 1443, in _execute_task_with_callbacks
    result = self._execute_task(context, self.task)
  File "/home/airflow/.local/lib/python3.6/site-packages/airflow/models/taskinstance.py", line 1499, in _execute_task
    result = execute_callable(context=context)
  File "/home/airflow/.local/lib/python3.6/site-packages/airflow/operators/python.py", line 151, in execute
    return_value = self.execute_callable()
  File "/home/airflow/.local/lib/python3.6/site-packages/airflow/operators/python.py", line 162, in execute_callable
    return self.python_callable(*self.op_args, **self.op_kwargs)
  File "/opt/airflow/dags/script/main_datamart.py", line 11, in load_datamart
    df_store = pd.read_csv("/opt/airflow/data_dim_fact/fact_store.csv", sep=',')
  File "/home/airflow/.local/lib/python3.6/site-packages/pandas/io/parsers.py", line 688, in read_csv
    return _read(filepath_or_buffer, kwds)
  File "/home/airflow/.local/lib/python3.6/site-packages/pandas/io/parsers.py", line 454, in _read
    parser = TextFileReader(fp_or_buf, **kwds)
  File "/home/airflow/.local/lib/python3.6/site-packages/pandas/io/parsers.py", line 948, in __init__
    self._make_engine(self.engine)
  File "/home/airflow/.local/lib/python3.6/site-packages/pandas/io/parsers.py", line 1180, in _make_engine
    self._engine = CParserWrapper(self.f, **self.options)
  File "/home/airflow/.local/lib/python3.6/site-packages/pandas/io/parsers.py", line 2010, in __init__
    self._reader = parsers.TextReader(src, **kwds)
  File "pandas/_libs/parsers.pyx", line 382, in pandas._libs.parsers.TextReader.__cinit__
  File "pandas/_libs/parsers.pyx", line 674, in pandas._libs.parsers.TextReader._setup_parser_source
FileNotFoundError: [Errno 2] No such file or directory: '/opt/airflow/data_dim_fact/fact_store.csv'
[2023-03-22 07:49:09,534] {taskinstance.py:1280} INFO - Marking task as FAILED. dag_id=load_to_datamart, task_id=load_to_datamart, execution_date=20230322T074903, start_date=20230322T074909, end_date=20230322T074909
[2023-03-22 07:49:09,561] {standard_task_runner.py:91} ERROR - Failed to execute job 4 for task load_to_datamart
Traceback (most recent call last):
  File "/home/airflow/.local/lib/python3.6/site-packages/airflow/task/task_runner/standard_task_runner.py", line 85, in _start_by_fork
    args.func(args, dag=self.dag)
  File "/home/airflow/.local/lib/python3.6/site-packages/airflow/cli/cli_parser.py", line 48, in command
    return func(*args, **kwargs)
  File "/home/airflow/.local/lib/python3.6/site-packages/airflow/utils/cli.py", line 92, in wrapper
    return f(*args, **kwargs)
  File "/home/airflow/.local/lib/python3.6/site-packages/airflow/cli/commands/task_command.py", line 292, in task_run
    _run_task_by_selected_method(args, dag, ti)
  File "/home/airflow/.local/lib/python3.6/site-packages/airflow/cli/commands/task_command.py", line 107, in _run_task_by_selected_method
    _run_raw_task(args, ti)
  File "/home/airflow/.local/lib/python3.6/site-packages/airflow/cli/commands/task_command.py", line 184, in _run_raw_task
    error_file=args.error_file,
  File "/home/airflow/.local/lib/python3.6/site-packages/airflow/utils/session.py", line 70, in wrapper
    return func(*args, session=session, **kwargs)
  File "/home/airflow/.local/lib/python3.6/site-packages/airflow/models/taskinstance.py", line 1324, in _run_raw_task
    self._execute_task_with_callbacks(context)
  File "/home/airflow/.local/lib/python3.6/site-packages/airflow/models/taskinstance.py", line 1443, in _execute_task_with_callbacks
    result = self._execute_task(context, self.task)
  File "/home/airflow/.local/lib/python3.6/site-packages/airflow/models/taskinstance.py", line 1499, in _execute_task
    result = execute_callable(context=context)
  File "/home/airflow/.local/lib/python3.6/site-packages/airflow/operators/python.py", line 151, in execute
    return_value = self.execute_callable()
  File "/home/airflow/.local/lib/python3.6/site-packages/airflow/operators/python.py", line 162, in execute_callable
    return self.python_callable(*self.op_args, **self.op_kwargs)
  File "/opt/airflow/dags/script/main_datamart.py", line 11, in load_datamart
    df_store = pd.read_csv("/opt/airflow/data_dim_fact/fact_store.csv", sep=',')
  File "/home/airflow/.local/lib/python3.6/site-packages/pandas/io/parsers.py", line 688, in read_csv
    return _read(filepath_or_buffer, kwds)
  File "/home/airflow/.local/lib/python3.6/site-packages/pandas/io/parsers.py", line 454, in _read
    parser = TextFileReader(fp_or_buf, **kwds)
  File "/home/airflow/.local/lib/python3.6/site-packages/pandas/io/parsers.py", line 948, in __init__
    self._make_engine(self.engine)
  File "/home/airflow/.local/lib/python3.6/site-packages/pandas/io/parsers.py", line 1180, in _make_engine
    self._engine = CParserWrapper(self.f, **self.options)
  File "/home/airflow/.local/lib/python3.6/site-packages/pandas/io/parsers.py", line 2010, in __init__
    self._reader = parsers.TextReader(src, **kwds)
  File "pandas/_libs/parsers.pyx", line 382, in pandas._libs.parsers.TextReader.__cinit__
  File "pandas/_libs/parsers.pyx", line 674, in pandas._libs.parsers.TextReader._setup_parser_source
FileNotFoundError: [Errno 2] No such file or directory: '/opt/airflow/data_dim_fact/fact_store.csv'
[2023-03-22 07:49:09,592] {local_task_job.py:154} INFO - Task exited with return code 1
[2023-03-22 07:49:09,658] {local_task_job.py:264} INFO - 0 downstream tasks scheduled from follow-on schedule check
