[2023-03-21 03:48:34,102] {taskinstance.py:1035} INFO - Dependencies all met for <TaskInstance: transform_etl.load_postgres manual__2023-03-21T03:48:08.323060+00:00 [queued]>
[2023-03-21 03:48:34,118] {taskinstance.py:1035} INFO - Dependencies all met for <TaskInstance: transform_etl.load_postgres manual__2023-03-21T03:48:08.323060+00:00 [queued]>
[2023-03-21 03:48:34,119] {taskinstance.py:1241} INFO - 
--------------------------------------------------------------------------------
[2023-03-21 03:48:34,120] {taskinstance.py:1242} INFO - Starting attempt 1 of 1
[2023-03-21 03:48:34,120] {taskinstance.py:1243} INFO - 
--------------------------------------------------------------------------------
[2023-03-21 03:48:34,143] {taskinstance.py:1262} INFO - Executing <Task(PythonOperator): load_postgres> on 2023-03-21 03:48:08.323060+00:00
[2023-03-21 03:48:34,149] {standard_task_runner.py:52} INFO - Started process 693 to run task
[2023-03-21 03:48:34,152] {standard_task_runner.py:76} INFO - Running: ['***', 'tasks', 'run', 'transform_etl', 'load_postgres', 'manual__2023-03-21T03:48:08.323060+00:00', '--job-id', '19', '--raw', '--subdir', 'DAGS_FOLDER/etl.py', '--cfg-path', '/tmp/tmpqfnb5isx', '--error-file', '/tmp/tmp2djrz478']
[2023-03-21 03:48:34,153] {standard_task_runner.py:77} INFO - Job 19: Subtask load_postgres
[2023-03-21 03:48:34,216] {logging_mixin.py:109} INFO - Running <TaskInstance: transform_etl.load_postgres manual__2023-03-21T03:48:08.323060+00:00 [running]> on host 8d5c7b966855
[2023-03-21 03:48:34,278] {taskinstance.py:1414} INFO - Exporting the following env vars:
AIRFLOW_CTX_DAG_OWNER=***
AIRFLOW_CTX_DAG_ID=transform_etl
AIRFLOW_CTX_TASK_ID=load_postgres
AIRFLOW_CTX_EXECUTION_DATE=2023-03-21T03:48:08.323060+00:00
AIRFLOW_CTX_DAG_RUN_ID=manual__2023-03-21T03:48:08.323060+00:00
[2023-03-21 03:48:37,282] {taskinstance.py:1686} ERROR - Task failed with exception
Traceback (most recent call last):
  File "/home/airflow/.local/lib/python3.6/site-packages/airflow/models/taskinstance.py", line 1324, in _run_raw_task
    self._execute_task_with_callbacks(context)
  File "/home/airflow/.local/lib/python3.6/site-packages/airflow/models/taskinstance.py", line 1443, in _execute_task_with_callbacks
    result = self._execute_task(context, self.task)
  File "/home/airflow/.local/lib/python3.6/site-packages/airflow/models/taskinstance.py", line 1499, in _execute_task
    result = execute_callable(context=context)
  File "/home/airflow/.local/lib/python3.6/site-packages/airflow/operators/python.py", line 151, in execute
    return_value = self.execute_callable()
  File "/home/airflow/.local/lib/python3.6/site-packages/airflow/operators/python.py", line 162, in execute_callable
    return self.python_callable(*self.op_args, **self.op_kwargs)
  File "/opt/airflow/dags/script/load.py", line 12, in load_mysql
    df.to_sql("lasVegas",engine)
  File "/home/airflow/.local/lib/python3.6/site-packages/pandas/core/generic.py", line 2615, in to_sql
    method=method,
  File "/home/airflow/.local/lib/python3.6/site-packages/pandas/io/sql.py", line 598, in to_sql
    method=method,
  File "/home/airflow/.local/lib/python3.6/site-packages/pandas/io/sql.py", line 1393, in to_sql
    table.create()
  File "/home/airflow/.local/lib/python3.6/site-packages/pandas/io/sql.py", line 723, in create
    raise ValueError(f"Table '{self.name}' already exists.")
ValueError: Table 'lasVegas' already exists.
[2023-03-21 03:48:37,310] {taskinstance.py:1280} INFO - Marking task as FAILED. dag_id=transform_etl, task_id=load_postgres, execution_date=20230321T034808, start_date=20230321T034834, end_date=20230321T034837
[2023-03-21 03:48:37,326] {standard_task_runner.py:91} ERROR - Failed to execute job 19 for task load_postgres
Traceback (most recent call last):
  File "/home/airflow/.local/lib/python3.6/site-packages/airflow/task/task_runner/standard_task_runner.py", line 85, in _start_by_fork
    args.func(args, dag=self.dag)
  File "/home/airflow/.local/lib/python3.6/site-packages/airflow/cli/cli_parser.py", line 48, in command
    return func(*args, **kwargs)
  File "/home/airflow/.local/lib/python3.6/site-packages/airflow/utils/cli.py", line 92, in wrapper
    return f(*args, **kwargs)
  File "/home/airflow/.local/lib/python3.6/site-packages/airflow/cli/commands/task_command.py", line 292, in task_run
    _run_task_by_selected_method(args, dag, ti)
  File "/home/airflow/.local/lib/python3.6/site-packages/airflow/cli/commands/task_command.py", line 107, in _run_task_by_selected_method
    _run_raw_task(args, ti)
  File "/home/airflow/.local/lib/python3.6/site-packages/airflow/cli/commands/task_command.py", line 184, in _run_raw_task
    error_file=args.error_file,
  File "/home/airflow/.local/lib/python3.6/site-packages/airflow/utils/session.py", line 70, in wrapper
    return func(*args, session=session, **kwargs)
  File "/home/airflow/.local/lib/python3.6/site-packages/airflow/models/taskinstance.py", line 1324, in _run_raw_task
    self._execute_task_with_callbacks(context)
  File "/home/airflow/.local/lib/python3.6/site-packages/airflow/models/taskinstance.py", line 1443, in _execute_task_with_callbacks
    result = self._execute_task(context, self.task)
  File "/home/airflow/.local/lib/python3.6/site-packages/airflow/models/taskinstance.py", line 1499, in _execute_task
    result = execute_callable(context=context)
  File "/home/airflow/.local/lib/python3.6/site-packages/airflow/operators/python.py", line 151, in execute
    return_value = self.execute_callable()
  File "/home/airflow/.local/lib/python3.6/site-packages/airflow/operators/python.py", line 162, in execute_callable
    return self.python_callable(*self.op_args, **self.op_kwargs)
  File "/opt/airflow/dags/script/load.py", line 12, in load_mysql
    df.to_sql("lasVegas",engine)
  File "/home/airflow/.local/lib/python3.6/site-packages/pandas/core/generic.py", line 2615, in to_sql
    method=method,
  File "/home/airflow/.local/lib/python3.6/site-packages/pandas/io/sql.py", line 598, in to_sql
    method=method,
  File "/home/airflow/.local/lib/python3.6/site-packages/pandas/io/sql.py", line 1393, in to_sql
    table.create()
  File "/home/airflow/.local/lib/python3.6/site-packages/pandas/io/sql.py", line 723, in create
    raise ValueError(f"Table '{self.name}' already exists.")
ValueError: Table 'lasVegas' already exists.
[2023-03-21 03:48:37,377] {local_task_job.py:154} INFO - Task exited with return code 1
[2023-03-21 03:48:37,426] {local_task_job.py:264} INFO - 0 downstream tasks scheduled from follow-on schedule check
